Workbook

Sheet Despesas Detalhe
A1: Ano | B1: Mês | C1: Dia | D1: Vencimento | E1: Data Pagamento | F1: Despesas Totais | G1: Contas | H1: Categoria | I1: Tipo de Gasto | J1: Pagamento | K1: Status do Pagamento
A2: =YEAR(Tabela135[[#This Row],[Vencimento]]) -> 2023 | B2: =TEXT(D2,"mmmm") -> abril | C2: =DAY(Tabela135[[#This Row],[Vencimento]]) -> 5 | D2: 45021 | E2: 45021 | F2: 150 | G2: Água | H2: Moradia | I2: Fixo | J2: Pago | K2: {=_xlfn.IFS(AND(Tabela135[[#This Row],[Data Pagamento]]="",Tabela135[[#This Row],[Vencimento]]<TODAY()),"Atrasado",AND(Tabela135[[#This Row],[Data Pagamento]]="",Tabela135[[#This Row],[Vencimento]]>TODAY()),"Em Aberto",Tabela135[[#This Row],[Data Pagamento]]>Tabela135[[#This Row],[Vencimento]],"Pago com Atraso",Tabela135[[#This Row],[Data Pagamento]]<=Tabela135[[#This Row],[Vencimento]],"Em dia")} -> Em dia
A3: =YEAR(Tabela135[[#This Row],[Vencimento]]) -> 2023 | B3: =TEXT(D3,"mmmm") -> abril | C3: =DAY(Tabela135[[#This Row],[Vencimento]]) -> 5 | D3: 45021 | E3: 45021 | F3: 350 | G3: Luz | H3: Moradia | I3: Fixo | J3: Pago | K3: {=_xlfn.IFS(AND(Tabela135[[#This Row],[Data Pagamento]]="",Tabela135[[#This Row],[Vencimento]]<TODAY()),"Atrasado",AND(Tabela135[[#This Row],[Data Pagamento]]="",Tabela135[[#This Row],[Vencimento]]>TODAY()),"Em Aberto",Tabela135[[#This Row],[Data Pagamento]]>Tabela135[[#This Row],[Vencimento]],"Pago com Atraso",Tabela135[[#This Row],[Data Pagamento]]<=Tabela135[[#This Row],[Vencimento]],"Em dia")} -> Em dia
A4: =YEAR(Tabela135[[#This Row],[Vencimento]]) -> 2023 | B4: =TEXT(D4,"mmmm") -> abril | C4: =DAY(Tabela135[[#This Row],[Vencimento]]) -> 20 | D4: 45036 | E4: 45036 | F4: 100 | G4: Internet | H4: Moradia | I4: Fixo | J4: Pago | K4: {=_xlfn.IFS(AND(Tabela135[[#This Row],[Data Pagamento]]="",Tabela135[[#This Row],[Vencimento]]<TODAY()),"Atrasado",AND(Tabela135[[#This Row],[Data Pagamento]]="",Tabela135[[#This Row],[Vencimento]]>TODAY()),"Em Aberto",Tabela135[[#This Row],[Data Pagamento]]>Tabela135[[#This Row],[Vencimento]],"Pago com Atraso",Tabela135[[#This Row],[Data Pagamento]]<=Tabela135[[#This Row],[Vencimento]],"Em dia")} -> Em dia
A5: =YEAR(Tabela135[[#This Row],[Vencimento]]) -> 2023 | B5: =TEXT(D5,"mmmm") -> abril | C5: =DAY(Tabela135[[#This Row],[Vencimento]]) -> 20 | D5: 45036 | E5: 45036 | F5: 802 | G5: Cartão Nubank | H5: Cartão de Crédito | I5: Variável | J5: Pago | K5: {=_xlfn.IFS(AND(Tabela135[[#This Row],[Data Pagamento]]="",Tabela135[[#This Row],[Vencimento]]<TODAY()),"Atrasado",AND(Tabela135[[#This Row],[Data Pagamento]]="",Tabela135[[#This Row],[Vencimento]]>TODAY()),"Em Aberto",Tabela135[[#This Row],[Data Pagamento]]>Tabela135[[#This Row],[Vencimento]],"Pago com Atraso",Tabela135[[#This Row],[Data Pagamento]]<=Tabela135[[#This Row],[Vencimento]],"Em dia")} -> Em dia
A6: =YEAR(Tabela135[[#This Row],[Vencimento]]) -> 2023 | B6: =TEXT(D6,"mmmm") -> abril | C6: =DAY(Tabela135[[#This Row],[Vencimento]]) -> 20 | D6: 45036 | E6: 45036 | F6: 100 | G6: Banho Cachorro | H6: Pet | I6: Fixo | J6: Pago | K6: {=_xlfn.IFS(AND(Tabela135[[#This Row],[Data Pagamento]]="",Tabela135[[#This Row],[Vencimento]]<TODAY()),"Atrasado",AND(Tabela135[[#This Row],[Data Pagamento]]="",Tabela135[[#This Row],[Vencimento]]>TODAY()),"Em Aberto",Tabela135[[#This Row],[Data Pagamento]]>Tabela135[[#This Row],[Vencimento]],"Pago com Atraso",Tabela135[[#This Row],[Data Pagamento]]<=Tabela135[[#This Row],[Vencimento]],"Em dia")} -> Em dia
A7: =YEAR(Tabela135[[#This Row],[Vencimento]]) -> 2023 | B7: =TEXT(D7,"mmmm") -> abril | C7: =DAY(Tabela135[[#This Row],[Vencimento]]) -> 5 | D7: 45021 | E7: 45021 | F7: 2500 | G7: Aluguel | H7: Moradia | I7: Fixo | J7: Pago | K7: {=_xlfn.IFS(AND(Tabela135[[#This Row],[Data Pagamento]]="",Tabela135[[#This Row],[Vencimento]]<TODAY()),"Atrasado",AND(Tabela135[[#This Row],[Data Pagamento]]="",Tabela135[[#This Row],[Vencimento]]>TODAY()),"Em Aberto",Tabela135[[#This Row],[Data Pagamento]]>Tabela135[[#This Row],[Vencimento]],"Pago com Atraso",Tabela135[[#This Row],[Data Pagamento]]<=Tabela135[[#This Row],[Vencimento]],"Em dia")} -> Em dia
A8: =YEAR(Tabela135[[#This Row],[Vencimento]]) -> 2023 | B8: =TEXT(D8,"mmmm") -> abril | C8: =DAY(Tabela135[[#This Row],[Vencimento]]) -> 20 | D8: 45036 | E8: 45036 | F8: 800 | G8: Creche | H8: Educação | I8: Fixo | J8: Pago | K8: {=_xlfn.IFS(AND(Tabela135[[#This Row],[Data Pagamento]]="",Tabela135[[#This Row],[Vencimento]]<TODAY()),"Atrasado",AND(Tabela135[[#This Row],[Data Pagamento]]="",Tabela135[[#This Row],[Vencimento]]>TODAY()),"Em Aberto",Tabela135[[#This Row],[Data Pagamento]]>Tabela135[[#This Row],[Vencimento]],"Pago com Atraso",Tabela135[[#This Row],[Data Pagamento]]<=Tabela135[[#This Row],[Vencimento]],"Em dia")} -> Em dia
A9: =YEAR(Tabela135[[#This Row],[Vencimento]]) -> 2023 | B9: =TEXT(D9,"mmmm") -> abril | C9: =DAY(Tabela135[[#This Row],[Vencimento]]) -> 20 | D9: 45036 | E9: 45036 | F9: 1000 | G9: Financiamento Carro | H9: Automóvel | I9: Fixo | J9: Pago | K9: {=_xlfn.IFS(AND(Tabela135[[#This Row],[Data Pagamento]]="",Tabela135[[#This Row],[Vencimento]]<TODAY()),"Atrasado",AND(Tabela135[[#This Row],[Data Pagamento]]="",Tabela135[[#This Row],[Vencimento]]>TODAY()),"Em Aberto",Tabela135[[#This Row],[Data Pagamento]]>Tabela135[[#This Row],[Vencimento]],"Pago com Atraso",Tabela135[[#This Row],[Data Pagamento]]<=Tabela135[[#This Row],[Vencimento]],"Em dia")} -> Em dia
A10: =YEAR(Tabela135[[#This Row],[Vencimento]]) -> 2023 | B10: =TEXT(D10,"mmmm") -> abril | C10: =DAY(Tabela135[[#This Row],[Vencimento]]) -> 20 | D10: 45036 | E10: 45036 | F10: 133 | G10: Cartão Santander | H10: Cartão de Crédito | I10: Variável | J10: Pago | K10: {=_xlfn.IFS(AND(Tabela135[[#This Row],[Data Pagamento]]="",Tabela135[[#This Row],[Vencimento]]<TODAY()),"Atrasado",AND(Tabela135[[#This Row],[Data Pagamento]]="",Tabela135[[#This Row],[Vencimento]]>TODAY()),"Em Aberto",Tabela135[[#This Row],[Data Pagamento]]>Tabela135[[#This Row],[Vencimento]],"Pago com Atraso",Tabela135[[#This Row],[Data Pagamento]]<=Tabela135[[#This Row],[Vencimento]],"Em dia")} -> Em dia
A11: =YEAR(Tabela135[[#This Row],[Vencimento]]) -> 2023 | B11: =TEXT(D11,"mmmm") -> agosto | C11: =DAY(Tabela135[[#This Row],[Vencimento]]) -> 5 | D11: 45143 | E11: 45143 | F11: 150 | G11: Água | H11: Moradia | I11: Fixo | J11: Pago | K11: {=_xlfn.IFS(AND(Tabela135[[#This Row],[Data Pagamento]]="",Tabela135[[#This Row],[Vencimento]]<TODAY()),"Atrasado",AND(Tabela135[[#This Row],[Data Pagamento]]="",Tabela135[[#This Row],[Vencimento]]>TODAY()),"Em Aberto",Tabela135[[#This Row],[Data Pagamento]]>Tabela135[[#This Row],[Vencimento]],"Pago com Atraso",Tabela135[[#This Row],[Data Pagamento]]<=Tabela135[[#This Row],[Vencimento]],"Em dia")} -> Em dia
A12: =YEAR(Tabela135[[#This Row],[Vencimento]]) -> 2023 | B12: =TEXT(D12,"mmmm") -> agosto | C12: =DAY(Tabela135[[#This Row],[Vencimento]]) -> 5 | D12: 45143 | E12: 45143 | F12: 350 | G12: Luz | H12: Moradia | I12: Fixo | J12: Pago | K12: {=_xlfn.IFS(AND(Tabela135[[#This Row],[Data Pagamento]]="",Tabela135[[#This Row],[Vencimento]]<TODAY()),"Atrasado",AND(Tabela135[[#This Row],[Data Pagamento]]="",Tabela135[[#This Row],[Vencimento]]>TODAY()),"Em Aberto",Tabela135[[#This Row],[Data Pagamento]]>Tabela135[[#This Row],[Vencimento]],"Pago com Atraso",Tabela135[[#This Row],[Data Pagamento]]<=Tabela135[[#This Row],[Vencimento]],"Em dia")} -> Em dia
A13: =YEAR(Tabela135[[#This Row],[Vencimento]]) -> 2023 | B13: =TEXT(D13,"mmmm") -> agosto | C13: =DAY(Tabela135[[#This Row],[Vencimento]]) -> 20 | D13: 45158 | E13: 45160 | F13: 100 | G13: Internet | H13: Moradia | I13: Fixo | J13: Pago | K13: {=_xlfn.IFS(AND(Tabela135[[#This Row],[Data Pagamento]]="",Tabela135[[#This Row],[Vencimento]]<TODAY()),"Atrasado",AND(Tabela135[[#This Row],[Data Pagamento]]="",Tabela135[[#This Row],[Vencimento]]>TODAY()),"Em Aberto",Tabela135[[#This Row],[Data Pagamento]]>Tabela135[[#This Row],[Vencimento]],"Pago com Atraso",Tabela135[[#This Row],[Data Pagamento]]<=Tabela135[[#This Row],[Vencimento]],"Em dia")} -> Pago com Atraso
... A335: =YEAR(Tabela135[[#This Row],[Vencimento]]) -> 2026 | B335: =TEXT(D335,"mmmm") -> abril | C335: =DAY(Tabela135[[#This Row],[Vencimento]]) -> 20 | D335: 46132 | E335: 46132 | F335: 104 | G335: Compras Online | H335: E-Commerce | I335: Variável | J335: Pago | K335: {=_xlfn.IFS(AND(Tabela135[[#This Row],[Data Pagamento]]="",Tabela135[[#This Row],[Vencimento]]<TODAY()),"Atrasado",AND(Tabela135[[#This Row],[Data Pagamento]]="",Tabela135[[#This Row],[Vencimento]]>TODAY()),"Em Aberto",Tabela135[[#This Row],[Data Pagamento]]>Tabela135[[#This Row],[Vencimento]],"Pago com Atraso",Tabela135[[#This Row],[Data Pagamento]]<=Tabela135[[#This Row],[Vencimento]],"Em dia")} -> Em dia
A336: =YEAR(Tabela135[[#This Row],[Vencimento]]) -> 2026 | B336: =TEXT(D336,"mmmm") -> agosto | C336: =DAY(Tabela135[[#This Row],[Vencimento]]) -> 6 | D336: 46240 | F336: 160 | G336: Água | H336: Moradia | I336: Fixo | J336: Não Pago | K336: {=_xlfn.IFS(AND(Tabela135[[#This Row],[Data Pagamento]]="",Tabela135[[#This Row],[Vencimento]]<TODAY()),"Atrasado",AND(Tabela135[[#This Row],[Data Pagamento]]="",Tabela135[[#This Row],[Vencimento]]>TODAY()),"Em Aberto",Tabela135[[#This Row],[Data Pagamento]]>Tabela135[[#This Row],[Vencimento]],"Pago com Atraso",Tabela135[[#This Row],[Data Pagamento]]<=Tabela135[[#This Row],[Vencimento]],"Em dia")} -> Em Aberto
A337: =YEAR(Tabela135[[#This Row],[Vencimento]]) -> 2026 | B337: =TEXT(D337,"mmmm") -> agosto | C337: =DAY(Tabela135[[#This Row],[Vencimento]]) -> 6 | D337: 46240 | F337: 350 | G337: Luz | H337: Moradia | I337: Fixo | J337: Não Pago | K337: {=_xlfn.IFS(AND(Tabela135[[#This Row],[Data Pagamento]]="",Tabela135[[#This Row],[Vencimento]]<TODAY()),"Atrasado",AND(Tabela135[[#This Row],[Data Pagamento]]="",Tabela135[[#This Row],[Vencimento]]>TODAY()),"Em Aberto",Tabela135[[#This Row],[Data Pagamento]]>Tabela135[[#This Row],[Vencimento]],"Pago com Atraso",Tabela135[[#This Row],[Data Pagamento]]<=Tabela135[[#This Row],[Vencimento]],"Em dia")} -> Em Aberto
A338: =YEAR(Tabela135[[#This Row],[Vencimento]]) -> 2026 | B338: =TEXT(D338,"mmmm") -> agosto | C338: =DAY(Tabela135[[#This Row],[Vencimento]]) -> 20 | D338: 46254 | F338: 100 | G338: Internet | H338: Moradia | I338: Fixo | J338: Não Pago | K338: {=_xlfn.IFS(AND(Tabela135[[#This Row],[Data Pagamento]]="",Tabela135[[#This Row],[Vencimento]]<TODAY()),"Atrasado",AND(Tabela135[[#This Row],[Data Pagamento]]="",Tabela135[[#This Row],[Vencimento]]>TODAY()),"Em Aberto",Tabela135[[#This Row],[Data Pagamento]]>Tabela135[[#This Row],[Vencimento]],"Pago com Atraso",Tabela135[[#This Row],[Data Pagamento]]<=Tabela135[[#This Row],[Vencimento]],"Em dia")} -> Em Aberto
A339: =YEAR(Tabela135[[#This Row],[Vencimento]]) -> 2026 | B339: =TEXT(D339,"mmmm") -> agosto | C339: =DAY(Tabela135[[#This Row],[Vencimento]]) -> 20 | D339: 46254 | F339: 67 | G339: Cartão Nubank | H339: Cartão de Crédito | I339: Variável | J339: Não Pago | K339: {=_xlfn.IFS(AND(Tabela135[[#This Row],[Data Pagamento]]="",Tabela135[[#This Row],[Vencimento]]<TODAY()),"Atrasado",AND(Tabela135[[#This Row],[Data Pagamento]]="",Tabela135[[#This Row],[Vencimento]]>TODAY()),"Em Aberto",Tabela135[[#This Row],[Data Pagamento]]>Tabela135[[#This Row],[Vencimento]],"Pago com Atraso",Tabela135[[#This Row],[Data Pagamento]]<=Tabela135[[#This Row],[Vencimento]],"Em dia")} -> Em Aberto
A340: =YEAR(Tabela135[[#This Row],[Vencimento]]) -> 2026 | B340: =TEXT(D340,"mmmm") -> agosto | C340: =DAY(Tabela135[[#This Row],[Vencimento]]) -> 20 | D340: 46254 | F340: 100 | G340: Banho Cachorro | H340: Pet | I340: Fixo | J340: Não Pago | K340: {=_xlfn.IFS(AND(Tabela135[[#This Row],[Data Pagamento]]="",Tabela135[[#This Row],[Vencimento]]<TODAY()),"Atrasado",AND(Tabela135[[#This Row],[Data Pagamento]]="",Tabela135[[#This Row],[Vencimento]]>TODAY()),"Em Aberto",Tabela135[[#This Row],[Data Pagamento]]>Tabela135[[#This Row],[Vencimento]],"Pago com Atraso",Tabela135[[#This Row],[Data Pagamento]]<=Tabela135[[#This Row],[Vencimento]],"Em dia")} -> Em Aberto
A341: =YEAR(Tabela135[[#This Row],[Vencimento]]) -> 2026 | B341: =TEXT(D341,"mmmm") -> agosto | C341: =DAY(Tabela135[[#This Row],[Vencimento]]) -> 6 | D341: 46240 | F341: 2500 | G341: Aluguel | H341: Moradia | I341: Fixo | J341: Não Pago | K341: {=_xlfn.IFS(AND(Tabela135[[#This Row],[Data Pagamento]]="",Tabela135[[#This Row],[Vencimento]]<TODAY()),"Atrasado",AND(Tabela135[[#This Row],[Data Pagamento]]="",Tabela135[[#This Row],[Vencimento]]>TODAY()),"Em Aberto",Tabela135[[#This Row],[Data Pagamento]]>Tabela135[[#This Row],[Vencimento]],"Pago com Atraso",Tabela135[[#This Row],[Data Pagamento]]<=Tabela135[[#This Row],[Vencimento]],"Em dia")} -> Em Aberto
A342: =YEAR(Tabela135[[#This Row],[Vencimento]]) -> 2026 | B342: =TEXT(D342,"mmmm") -> agosto | C342: =DAY(Tabela135[[#This Row],[Vencimento]]) -> 20 | D342: 46254 | F342: 800 | G342: Creche | H342: Educação | I342: Fixo | J342: Não Pago | K342: {=_xlfn.IFS(AND(Tabela135[[#This Row],[Data Pagamento]]="",Tabela135[[#This Row],[Vencimento]]<TODAY()),"Atrasado",AND(Tabela135[[#This Row],[Data Pagamento]]="",Tabela135[[#This Row],[Vencimento]]>TODAY()),"Em Aberto",Tabela135[[#This Row],[Data Pagamento]]>Tabela135[[#This Row],[Vencimento]],"Pago com Atraso",Tabela135[[#This Row],[Data Pagamento]]<=Tabela135[[#This Row],[Vencimento]],"Em dia")} -> Em Aberto
A343: =YEAR(Tabela135[[#This Row],[Vencimento]]) -> 2026 | B343: =TEXT(D343,"mmmm") -> agosto | C343: =DAY(Tabela135[[#This Row],[Vencimento]]) -> 20 | D343: 46254 | F343: 1000 | G343: Financiamento Carro | H343: Automóvel | I343: Fixo | J343: Não Pago | K343: {=_xlfn.IFS(AND(Tabela135[[#This Row],[Data Pagamento]]="",Tabela135[[#This Row],[Vencimento]]<TODAY()),"Atrasado",AND(Tabela135[[#This Row],[Data Pagamento]]="",Tabela135[[#This Row],[Vencimento]]>TODAY()),"Em Aberto",Tabela135[[#This Row],[Data Pagamento]]>Tabela135[[#This Row],[Vencimento]],"Pago com Atraso",Tabela135[[#This Row],[Data Pagamento]]<=Tabela135[[#This Row],[Vencimento]],"Em dia")} -> Em Aberto
A344: =YEAR(Tabela135[[#This Row],[Vencimento]]) -> 2026 | B344: =TEXT(D344,"mmmm") -> agosto | C344: =DAY(Tabela135[[#This Row],[Vencimento]]) -> 20 | D344: 46254 | F344: 45 | G344: Cartão Santander | H344: Cartão de Crédito | I344: Variável | J344: Não Pago | K344: {=_xlfn.IFS(AND(Tabela135[[#This Row],[Data Pagamento]]="",Tabela135[[#This Row],[Vencimento]]<TODAY()),"Atrasado",AND(Tabela135[[#This Row],[Data Pagamento]]="",Tabela135[[#This Row],[Vencimento]]>TODAY()),"Em Aberto",Tabela135[[#This Row],[Data Pagamento]]>Tabela135[[#This Row],[Vencimento]],"Pago com Atraso",Tabela135[[#This Row],[Data Pagamento]]<=Tabela135[[#This Row],[Vencimento]],"Em dia")} -> Em Aberto
A345: =YEAR(Tabela135[[#This Row],[Vencimento]]) -> 2026 | B345: =TEXT(D345,"mmmm") -> dezembro | C345: =DAY(Tabela135[[#This Row],[Vencimento]]) -> 6 | D345: 46362 | F345: 160 | G345: Água | H345: Moradia | I345: Fixo | J345: Não Pago | K345: {=_xlfn.IFS(AND(Tabela135[[#This Row],[Data Pagamento]]="",Tabela135[[#This Row],[Vencimento]]<TODAY()),"Atrasado",AND(Tabela135[[#This Row],[Data Pagamento]]="",Tabela135[[#This Row],[Vencimento]]>TODAY()),"Em Aberto",Tabela135[[#This Row],[Data Pagamento]]>Tabela135[[#This Row],[Vencimento]],"Pago com Atraso",Tabela135[[#This Row],[Data Pagamento]]<=Tabela135[[#This Row],[Vencimento]],"Em dia")} -> Em Aberto
A346: =YEAR(Tabela135[[#This Row],[Vencimento]]) -> 2026 | B346: =TEXT(D346,"mmmm") -> dezembro | C346: =DAY(Tabela135[[#This Row],[Vencimento]]) -> 6 | D346: 46362 | F346: 350 | G346: Luz | H346: Moradia | I346: Fixo | J346: Não Pago | K346: {=_xlfn.IFS(AND(Tabela135[[#This Row],[Data Pagamento]]="",Tabela135[[#This Row],[Vencimento]]<TODAY()),"Atrasado",AND(Tabela135[[#This Row],[Data Pagamento]]="",Tabela135[[#This Row],[Vencimento]]>TODAY()),"Em Aberto",Tabela135[[#This Row],[Data Pagamento]]>Tabela135[[#This Row],[Vencimento]],"Pago com Atraso",Tabela135[[#This Row],[Data Pagamento]]<=Tabela135[[#This Row],[Vencimento]],"Em dia")} -> Em Aberto
A347: =YEAR(Tabela135[[#This Row],[Vencimento]]) -> 2026 | B347: =TEXT(D347,"mmmm") -> dezembro | C347: =DAY(Tabela135[[#This Row],[Vencimento]]) -> 20 | D347: 46376 | F347: 100 | G347: Internet | H347: Moradia | I347: Fixo | J347: Não Pago | K347: {=_xlfn.IFS(AND(Tabela135[[#This Row],[Data Pagamento]]="",Tabela135[[#This Row],[Vencimento]]<TODAY()),"Atrasado",AND(Tabela135[[#This Row],[Data Pagamento]]="",Tabela135[[#This Row],[Vencimento]]>TODAY()),"Em Aberto",Tabela135[[#This Row],[Data Pagamento]]>Tabela135[[#This Row],[Vencimento]],"Pago com Atraso",Tabela135[[#This Row],[Data Pagamento]]<=Tabela135[[#This Row],[Vencimento]],"Em dia")} -> Em Aberto
... A353: =YEAR(Tabela135[[#This Row],[Vencimento]]) -> 2026 | B353: =TEXT(D353,"mmmm") -> dezembro | C353: =DAY(Tabela135[[#This Row],[Vencimento]]) -> 20 | D353: 46376 | F353: 22 | G353: Cartão Santander | H353: Cartão de Crédito | I353: Variável | J353: Não Pago | K353: {=_xlfn.IFS(AND(Tabela135[[#This Row],[Data Pagamento]]="",Tabela135[[#This Row],[Vencimento]]<TODAY()),"Atrasado",AND(Tabela135[[#This Row],[Data Pagamento]]="",Tabela135[[#This Row],[Vencimento]]>TODAY()),"Em Aberto",Tabela135[[#This Row],[Data Pagamento]]>Tabela135[[#This Row],[Vencimento]],"Pago com Atraso",Tabela135[[#This Row],[Data Pagamento]]<=Tabela135[[#This Row],[Vencimento]],"Em dia")} -> Em Aberto
A354: =YEAR(Tabela135[[#This Row],[Vencimento]]) -> 2026 | B354: =TEXT(D354,"mmmm") -> fevereiro | C354: =DAY(Tabela135[[#This Row],[Vencimento]]) -> 6 | D354: 46059 | E354: 46075 | F354: 160 | G354: Água | H354: Moradia | I354: Fixo | J354: Pago | K354: {=_xlfn.IFS(AND(Tabela135[[#This Row],[Data Pagamento]]="",Tabela135[[#This Row],[Vencimento]]<TODAY()),"Atrasado",AND(Tabela135[[#This Row],[Data Pagamento]]="",Tabela135[[#This Row],[Vencimento]]>TODAY()),"Em Aberto",Tabela135[[#This Row],[Data Pagamento]]>Tabela135[[#This Row],[Vencimento]],"Pago com Atraso",Tabela135[[#This Row],[Data Pagamento]]<=Tabela135[[#This Row],[Vencimento]],"Em dia")} -> Pago com Atraso
A355: =YEAR(Tabela135[[#This Row],[Vencimento]]) -> 2026 | B355: =TEXT(D355,"mmmm") -> fevereiro | C355: =DAY(Tabela135[[#This Row],[Vencimento]]) -> 6 | D355: 46059 | E355: 46075 | F355: 350 | G355: Luz | H355: Moradia | I355: Fixo | J355: Pago | K355: {=_xlfn.IFS(AND(Tabela135[[#This Row],[Data Pagamento]]="",Tabela135[[#This Row],[Vencimento]]<TODAY()),"Atrasado",AND(Tabela135[[#This Row],[Data Pagamento]]="",Tabela135[[#This Row],[Vencimento]]>TODAY()),"Em Aberto",Tabela135[[#This Row],[Data Pagamento]]>Tabela135[[#This Row],[Vencimento]],"Pago com Atraso",Tabela135[[#This Row],[Data Pagamento]]<=Tabela135[[#This Row],[Vencimento]],"Em dia")} -> Pago com Atraso
A356: =YEAR(Tabela135[[#This Row],[Vencimento]]) -> 2026 | B356: =TEXT(D356,"mmmm") -> fevereiro | C356: =DAY(Tabela135[[#This Row],[Vencimento]]) -> 20 | D356: 46073 | E356: 46075 | F356: 100 | G356: Internet | H356: Moradia | I356: Fixo | J356: Pago | K356: {=_xlfn.IFS(AND(Tabela135[[#This Row],[Data Pagamento]]="",Tabela135[[#This Row],[Vencimento]]<TODAY()),"Atrasado",AND(Tabela135[[#This Row],[Data Pagamento]]="",Tabela135[[#This Row],[Vencimento]]>TODAY()),"Em Aberto",Tabela135[[#This Row],[Data Pagamento]]>Tabela135[[#This Row],[Vencimento]],"Pago com Atraso",Tabela135[[#This Row],[Data Pagamento]]<=Tabela135[[#This Row],[Vencimento]],"Em dia")} -> Pago com Atraso
A357: =YEAR(Tabela135[[#This Row],[Vencimento]]) -> 2026 | B357: =TEXT(D357,"mmmm") -> fevereiro | C357: =DAY(Tabela135[[#This Row],[Vencimento]]) -> 20 | D357: 46073 | E357: 46075 | F357: 987 | G357: Cartão Nubank | H357: Cartão de Crédito | I357: Variável | J357: Pago | K357: {=_xlfn.IFS(AND(Tabela135[[#This Row],[Data Pagamento]]="",Tabela135[[#This Row],[Vencimento]]<TODAY()),"Atrasado",AND(Tabela135[[#This Row],[Data Pagamento]]="",Tabela135[[#This Row],[Vencimento]]>TODAY()),"Em Aberto",Tabela135[[#This Row],[Data Pagamento]]>Tabela135[[#This Row],[Vencimento]],"Pago com Atraso",Tabela135[[#This Row],[Data Pagamento]]<=Tabela135[[#This Row],[Vencimento]],"Em dia")} -> Pago com Atraso
A358: =YEAR(Tabela135[[#This Row],[Vencimento]]) -> 2026 | B358: =TEXT(D358,"mmmm") -> fevereiro | C358: =DAY(Tabela135[[#This Row],[Vencimento]]) -> 20 | D358: 46073 | E358: 46072 | F358: 100 | G358: Banho Cachorro | H358: Pet | I358: Fixo | J358: Pago | K358: {=_xlfn.IFS(AND(Tabela135[[#This Row],[Data Pagamento]]="",Tabela135[[#This Row],[Vencimento]]<TODAY()),"Atrasado",AND(Tabela135[[#This Row],[Data Pagamento]]="",Tabela135[[#This Row],[Vencimento]]>TODAY()),"Em Aberto",Tabela135[[#This Row],[Data Pagamento]]>Tabela135[[#This Row],[Vencimento]],"Pago com Atraso",Tabela135[[#This Row],[Data Pagamento]]<=Tabela135[[#This Row],[Vencimento]],"Em dia")} -> Em dia
A359: =YEAR(Tabela135[[#This Row],[Vencimento]]) -> 2026 | B359: =TEXT(D359,"mmmm") -> fevereiro | C359: =DAY(Tabela135[[#This Row],[Vencimento]]) -> 6 | D359: 46059 | E359: 46059 | F359: 2500 | G359: Aluguel | H359: Moradia | I359: Fixo | J359: Pago | K359: {=_xlfn.IFS(AND(Tabela135[[#This Row],[Data Pagamento]]="",Tabela135[[#This Row],[Vencimento]]<TODAY()),"Atrasado",AND(Tabela135[[#This Row],[Data Pagamento]]="",Tabela135[[#This Row],[Vencimento]]>TODAY()),"Em Aberto",Tabela135[[#This Row],[Data Pagamento]]>Tabela135[[#This Row],[Vencimento]],"Pago com Atraso",Tabela135[[#This Row],[Data Pagamento]]<=Tabela135[[#This Row],[Vencimento]],"Em dia")} -> Em dia
A360: =YEAR(Tabela135[[#This Row],[Vencimento]]) -> 2026 | B360: =TEXT(D360,"mmmm") -> fevereiro | C360: =DAY(Tabela135[[#This Row],[Vencimento]]) -> 20 | D360: 46073 | E360: 46072 | F360: 800 | G360: Creche | H360: Educação | I360: Fixo | J360: Pago | K360: {=_xlfn.IFS(AND(Tabela135[[#This Row],[Data Pagamento]]="",Tabela135[[#This Row],[Vencimento]]<TODAY()),"Atrasado",AND(Tabela135[[#This Row],[Data Pagamento]]="",Tabela135[[#This Row],[Vencimento]]>TODAY()),"Em Aberto",Tabela135[[#This Row],[Data Pagamento]]>Tabela135[[#This Row],[Vencimento]],"Pago com Atraso",Tabela135[[#This Row],[Data Pagamento]]<=Tabela135[[#This Row],[Vencimento]],"Em dia")} -> Em dia
A361: =YEAR(Tabela135[[#This Row],[Vencimento]]) -> 2026 | B361: =TEXT(D361,"mmmm") -> fevereiro | C361: =DAY(Tabela135[[#This Row],[Vencimento]]) -> 20 | D361: 46073 | E361: 46072 | F361: 1000 | G361: Financiamento Carro | H361: Automóvel | I361: Fixo | J361: Pago | K361: {=_xlfn.IFS(AND(Tabela135[[#This Row],[Data Pagamento]]="",Tabela135[[#This Row],[Vencimento]]<TODAY()),"Atrasado",AND(Tabela135[[#This Row],[Data Pagamento]]="",Tabela135[[#This Row],[Vencimento]]>TODAY()),"Em Aberto",Tabela135[[#This Row],[Data Pagamento]]>Tabela135[[#This Row],[Vencimento]],"Pago com Atraso",Tabela135[[#This Row],[Data Pagamento]]<=Tabela135[[#This Row],[Vencimento]],"Em dia")} -> Em dia
A362: =YEAR(Tabela135[[#This Row],[Vencimento]]) -> 2026 | B362: =TEXT(D362,"mmmm") -> fevereiro | C362: =DAY(Tabela135[[#This Row],[Vencimento]]) -> 20 | D362: 46073 | E362: 46075 | F362: 212 | G362: Cartão Santander | H362: Cartão de Crédito | I362: Variável | J362: Pago | K362: {=_xlfn.IFS(AND(Tabela135[[#This Row],[Data Pagamento]]="",Tabela135[[#This Row],[Vencimento]]<TODAY()),"Atrasado",AND(Tabela135[[#This Row],[Data Pagamento]]="",Tabela135[[#This Row],[Vencimento]]>TODAY()),"Em Aberto",Tabela135[[#This Row],[Data Pagamento]]>Tabela135[[#This Row],[Vencimento]],"Pago com Atraso",Tabela135[[#This Row],[Data Pagamento]]<=Tabela135[[#This Row],[Vencimento]],"Em dia")} -> Pago com Atraso
A363: =YEAR(Tabela135[[#This Row],[Vencimento]]) -> 2026 | B363: =TEXT(D363,"mmmm") -> fevereiro | C363: =DAY(Tabela135[[#This Row],[Vencimento]]) -> 20 | D363: 46073 | E363: 46073 | F363: 101 | G363: Compras Online | H363: E-Commerce | I363: Variável | J363: Pago | K363: {=_xlfn.IFS(AND(Tabela135[[#This Row],[Data Pagamento]]="",Tabela135[[#This Row],[Vencimento]]<TODAY()),"Atrasado",AND(Tabela135[[#This Row],[Data Pagamento]]="",Tabela135[[#This Row],[Vencimento]]>TODAY()),"Em Aberto",Tabela135[[#This Row],[Data Pagamento]]>Tabela135[[#This Row],[Vencimento]],"Pago com Atraso",Tabela135[[#This Row],[Data Pagamento]]<=Tabela135[[#This Row],[Vencimento]],"Em dia")} -> Em dia
A364: =YEAR(Tabela135[[#This Row],[Vencimento]]) -> 2026 | B364: =TEXT(D364,"mmmm") -> janeiro | C364: =DAY(Tabela135[[#This Row],[Vencimento]]) -> 6 | D364: 46028 | E364: 46045 | F364: 160 | G364: Água | H364: Moradia | I364: Fixo | J364: Pago | K364: {=_xlfn.IFS(AND(Tabela135[[#This Row],[Data Pagamento]]="",Tabela135[[#This Row],[Vencimento]]<TODAY()),"Atrasado",AND(Tabela135[[#This Row],[Data Pagamento]]="",Tabela135[[#This Row],[Vencimento]]>TODAY()),"Em Aberto",Tabela135[[#This Row],[Data Pagamento]]>Tabela135[[#This Row],[Vencimento]],"Pago com Atraso",Tabela135[[#This Row],[Data Pagamento]]<=Tabela135[[#This Row],[Vencimento]],"Em dia")} -> Pago com Atraso
A365: =YEAR(Tabela135[[#This Row],[Vencimento]]) -> 2026 | B365: =TEXT(D365,"mmmm") -> janeiro | C365: =DAY(Tabela135[[#This Row],[Vencimento]]) -> 6 | D365: 46028 | E365: 46045 | F365: 350 | G365: Luz | H365: Moradia | I365: Fixo | J365: Pago | K365: {=_xlfn.IFS(AND(Tabela135[[#This Row],[Data Pagamento]]="",Tabela135[[#This Row],[Vencimento]]<TODAY()),"Atrasado",AND(Tabela135[[#This Row],[Data Pagamento]]="",Tabela135[[#This Row],[Vencimento]]>TODAY()),"Em Aberto",Tabela135[[#This Row],[Data Pagamento]]>Tabela135[[#This Row],[Vencimento]],"Pago com Atraso",Tabela135[[#This Row],[Data Pagamento]]<=Tabela135[[#This Row],[Vencimento]],"Em dia")} -> Pago com Atraso
... A373: =YEAR(Tabela135[[#This Row],[Vencimento]]) -> 2026 | B373: =TEXT(D373,"mmmm") -> janeiro | C373: =DAY(Tabela135[[#This Row],[Vencimento]]) -> 20 | D373: 46042 | E373: 46041 | F373: 122 | G373: Compras Online | H373: E-Commerce | I373: Variável | J373: Pago | K373: {=_xlfn.IFS(AND(Tabela135[[#This Row],[Data Pagamento]]="",Tabela135[[#This Row],[Vencimento]]<TODAY()),"Atrasado",AND(Tabela135[[#This Row],[Data Pagamento]]="",Tabela135[[#This Row],[Vencimento]]>TODAY()),"Em Aberto",Tabela135[[#This Row],[Data Pagamento]]>Tabela135[[#This Row],[Vencimento]],"Pago com Atraso",Tabela135[[#This Row],[Data Pagamento]]<=Tabela135[[#This Row],[Vencimento]],"Em dia")} -> Em dia
...

Sheet Despesas (Totalizadas)
D1: =TEXT(E1,"mmm-aaaa") -> mai-2025 | E1: 45807
C2: Ano | D2: Mês | E2: Data | F2: Período das Despesas | G2: Salário | H2: Despesas Totais | I2: Despesas Provisionadas | J2: Caixa | K2: Despesas em Aberto | L2: Desvio Caixa (%)
A3: =YEAR(E3) -> 2025 | B3: =MONTH(E3) -> 6 | C3: =YEAR(Tabela36[[#This Row],[Data]]) -> 2025 | D3: =TEXT(E3,"mmmm") -> junho | E3: 45823 | F3: ="01 a 14"&"/"&B3&"/"&A3 -> 01 a 14/6/2025 | G3: =3000+2500 -> 5500 | H3: =-SUMIFS('Despesas Detalhe'!$F:$F,'Despesas Detalhe'!$D:$D,">"&$E1,'Despesas Detalhe'!$D:$D,"<"&$E3) -> -3010 | I3: =-SUMIFS('Despesas Detalhe'!$F:$F,'Despesas Detalhe'!$E:$E,">"&$E1,'Despesas Detalhe'!$E:$E,"<"&$E3) -> -3010 | J3: =G3+I3 -> 2490 | K3: =IF((ABS(H3)+I3)<=0,"",ABS(H3)+I3) | L3: =J3/G3 -> 0.45272727
A4: =YEAR(E4) -> 2025 | B4: =MONTH(E4) -> 6 | C4: =YEAR(Tabela36[[#This Row],[Data]]) -> 2025 | D4: =TEXT(E4,"mmmm") -> junho | E4: 45838 | F4: ="15 a 30"&"/"&B3&"/"&A3 -> 15 a 30/6/2025 | G4: =2200+2000 -> 4200 | H4: =-SUMIFS('Despesas Detalhe'!$F:$F,'Despesas Detalhe'!$D:$D,">="&$E3,'Despesas Detalhe'!$D:$D,"<="&$E4) -> -3410 | I4: =-SUMIFS('Despesas Detalhe'!$F:$F,'Despesas Detalhe'!$E:$E,">="&$E3,'Despesas Detalhe'!$E:$E,"<="&$E4) -> -3410 | J4: =G4+I4 -> 790 | K4: =IF((ABS(H4)+I4)<=0,"",ABS(H4)+I4) | L4: =J4/G4 -> 0.18809524
A5: =YEAR(E5) -> 2025 | B5: =MONTH(E5) -> 7 | C5: =YEAR(Tabela36[[#This Row],[Data]]) -> 2025 | D5: =TEXT(E5,"mmmm") -> julho | E5: 45853 | F5: ="01 a 14"&"/"&B5&"/"&A5 -> 01 a 14/7/2025 | G5: =3000+2500 -> 5500 | H5: =-SUMIFS('Despesas Detalhe'!$F:$F,'Despesas Detalhe'!$D:$D,">"&$E4,'Despesas Detalhe'!$D:$D,"<"&$E5) -> -3010 | I5: =-SUMIFS('Despesas Detalhe'!$F:$F,'Despesas Detalhe'!$E:$E,">"&$E4,'Despesas Detalhe'!$E:$E,"<"&$E5) -> -3010 | J5: =G5+I5 -> 2490 | K5: =IF((ABS(H5)+I5)<=0,"",ABS(H5)+I5) | L5: =J5/G5 -> 0.45272727
A6: =YEAR(E6) -> 2025 | B6: =MONTH(E6) -> 7 | C6: =YEAR(Tabela36[[#This Row],[Data]]) -> 2025 | D6: =TEXT(E6,"mmmm") -> julho | E6: 45868 | F6: ="15 a 30"&"/"&B5&"/"&A5 -> 15 a 30/7/2025 | G6: =2200+2000 -> 4200 | H6: =-SUMIFS('Despesas Detalhe'!$F:$F,'Despesas Detalhe'!$D:$D,">="&$E5,'Despesas Detalhe'!$D:$D,"<="&$E6) -> -2687 | I6: =-SUMIFS('Despesas Detalhe'!$F:$F,'Despesas Detalhe'!$E:$E,">="&$E5,'Despesas Detalhe'!$E:$E,"<="&$E6) -> -2687 | J6: =G6+I6 -> 1513 | K6: =IF((ABS(H6)+I6)<=0,"",ABS(H6)+I6) | L6: =J6/G6 -> 0.3602381
A7: =YEAR(E7) -> 2025 | B7: =MONTH(E7) -> 8 | C7: =YEAR(Tabela36[[#This Row],[Data]]) -> 2025 | D7: =TEXT(E7,"mmmm") -> agosto | E7: 45884 | F7: ="01 a 14"&"/"&B7&"/"&A7 -> 01 a 14/8/2025 | G7: =3000+2500 -> 5500 | H7: =-SUMIFS('Despesas Detalhe'!$F:$F,'Despesas Detalhe'!$D:$D,">"&$E6,'Despesas Detalhe'!$D:$D,"<"&$E7) -> -3010 | I7: =-SUMIFS('Despesas Detalhe'!$F:$F,'Despesas Detalhe'!$E:$E,">"&$E6,'Despesas Detalhe'!$E:$E,"<"&$E7) -> -3010 | J7: =G7+I7 -> 2490 | K7: =IF((ABS(H7)+I7)<=0,"",ABS(H7)+I7) | L7: =J7/G7 -> 0.45272727
A8: =YEAR(E8) -> 2025 | B8: =MONTH(E8) -> 8 | C8: =YEAR(Tabela36[[#This Row],[Data]]) -> 2025 | D8: =TEXT(E8,"mmmm") -> agosto | E8: 45899 | F8: ="15 a 30"&"/"&B7&"/"&A7 -> 15 a 30/8/2025 | G8: =2200+2000 -> 4200 | H8: =-SUMIFS('Despesas Detalhe'!$F:$F,'Despesas Detalhe'!$D:$D,">="&$E7,'Despesas Detalhe'!$D:$D,"<="&$E8) -> -3001 | I8: =-SUMIFS('Despesas Detalhe'!$F:$F,'Despesas Detalhe'!$E:$E,">="&$E7,'Despesas Detalhe'!$E:$E,"<="&$E8) -> -3001 | J8: =G8+I8 -> 1199 | K8: =IF((ABS(H8)+I8)<=0,"",ABS(H8)+I8) | L8: =J8/G8 -> 0.28547619
A9: =YEAR(E9) -> 2025 | B9: =MONTH(E9) -> 9 | C9: =YEAR(Tabela36[[#This Row],[Data]]) -> 2025 | D9: =TEXT(E9,"mmmm") -> setembro | E9: 45915 | F9: ="01 a 14"&"/"&B9&"/"&A9 -> 01 a 14/9/2025 | G9: =3000+2500 -> 5500 | H9: =-SUMIFS('Despesas Detalhe'!$F:$F,'Despesas Detalhe'!$D:$D,">"&$E8,'Despesas Detalhe'!$D:$D,"<"&$E9) -> -3010 | I9: =-SUMIFS('Despesas Detalhe'!$F:$F,'Despesas Detalhe'!$E:$E,">"&$E8,'Despesas Detalhe'!$E:$E,"<"&$E9) -> -3010 | J9: =G9+I9 -> 2490 | K9: =IF((ABS(H9)+I9)<=0,"",ABS(H9)+I9) | L9: =J9/G9 -> 0.45272727
A10: =YEAR(E10) -> 2025 | B10: =MONTH(E10) -> 9 | C10: =YEAR(Tabela36[[#This Row],[Data]]) -> 2025 | D10: =TEXT(E10,"mmmm") -> setembro | E10: 45930 | F10: ="15 a 30"&"/"&B9&"/"&A9 -> 15 a 30/9/2025 | G10: =2200+2000 -> 4200 | H10: =-SUMIFS('Despesas Detalhe'!$F:$F,'Despesas Detalhe'!$D:$D,">="&$E9,'Despesas Detalhe'!$D:$D,"<="&$E10) -> -2820 | I10: =-SUMIFS('Despesas Detalhe'!$F:$F,'Despesas Detalhe'!$E:$E,">="&$E9,'Despesas Detalhe'!$E:$E,"<="&$E10) -> -2820 | J10: =G10+I10 -> 1380 | K10: =IF((ABS(H10)+I10)<=0,"",ABS(H10)+I10) | L10: =J10/G10 -> 0.32857143
A11: =YEAR(E11) -> 2025 | B11: =MONTH(E11) -> 10 | C11: =YEAR(Tabela36[[#This Row],[Data]]) -> 2025 | D11: =TEXT(E11,"mmmm") -> outubro | E11: 45945 | F11: ="01 a 14"&"/"&B11&"/"&A11 -> 01 a 14/10/2025 | G11: =3000+2500 -> 5500 | H11: =-SUMIFS('Despesas Detalhe'!$F:$F,'Despesas Detalhe'!$D:$D,">"&$E10,'Despesas Detalhe'!$D:$D,"<"&$E11) -> -3010 | I11: =-SUMIFS('Despesas Detalhe'!$F:$F,'Despesas Detalhe'!$E:$E,">"&$E10,'Despesas Detalhe'!$E:$E,"<"&$E11) -> -3010 | J11: =G11+I11 -> 2490 | K11: =IF((ABS(H11)+I11)<=0,"",ABS(H11)+I11) | L11: =J11/G11 -> 0.45272727
A12: =YEAR(E12) -> 2025 | B12: =MONTH(E12) -> 10 | C12: =YEAR(Tabela36[[#This Row],[Data]]) -> 2025 | D12: =TEXT(E12,"mmmm") -> outubro | E12: 45960 | F12: ="15 a 30"&"/"&B11&"/"&A11 -> 15 a 30/10/2025 | G12: =2200+2000 -> 4200 | H12: =-SUMIFS('Despesas Detalhe'!$F:$F,'Despesas Detalhe'!$D:$D,">="&$E11,'Despesas Detalhe'!$D:$D,"<="&$E12) -> -2589 | I12: =-SUMIFS('Despesas Detalhe'!$F:$F,'Despesas Detalhe'!$E:$E,">="&$E11,'Despesas Detalhe'!$E:$E,"<="&$E12) -> -2589 | J12: =G12+I12 -> 1611 | K12: =IF((ABS(H12)+I12)<=0,"",ABS(H12)+I12) | L12: =J12/G12 -> 0.38357143
A13: =YEAR(E13) -> 2025 | B13: =MONTH(E13) -> 11 | C13: =YEAR(Tabela36[[#This Row],[Data]]) -> 2025 | D13: =TEXT(E13,"mmmm") -> novembro | E13: 45976 | F13: ="01 a 14"&"/"&B13&"/"&A13 -> 01 a 14/11/2025 | G13: =3000+2500 -> 5500 | H13: =-SUMIFS('Despesas Detalhe'!$F:$F,'Despesas Detalhe'!$D:$D,">"&$E12,'Despesas Detalhe'!$D:$D,"<"&$E13) -> -3010 | I13: =-SUMIFS('Despesas Detalhe'!$F:$F,'Despesas Detalhe'!$E:$E,">"&$E12,'Despesas Detalhe'!$E:$E,"<"&$E13) -> -3010 | J13: =G13+I13 -> 2490 | K13: =IF((ABS(H13)+I13)<=0,"",ABS(H13)+I13) | L13: =J13/G13 -> 0.45272727
A14: =YEAR(E14) -> 2025 | B14: =MONTH(E14) -> 11 | C14: =YEAR(Tabela36[[#This Row],[Data]]) -> 2025 | D14: =TEXT(E14,"mmmm") -> novembro | E14: 45991 | F14: ="15 a 30"&"/"&B13&"/"&A13 -> 15 a 30/11/2025 | G14: =2200+2000 -> 4200 | H14: =-SUMIFS('Despesas Detalhe'!$F:$F,'Despesas Detalhe'!$D:$D,">="&$E13,'Despesas Detalhe'!$D:$D,"<="&$E14) -> -3110 | I14: =-SUMIFS('Despesas Detalhe'!$F:$F,'Despesas Detalhe'!$E:$E,">="&$E13,'Despesas Detalhe'!$E:$E,"<="&$E14) -> -3110 | J14: =G14+I14 -> 1090 | K14: =IF((ABS(H14)+I14)<=0,"",ABS(H14)+I14) | L14: =J14/G14 -> 0.25952381
A15: =YEAR(E15) -> 2025 | B15: =MONTH(E15) -> 12 | C15: =YEAR(Tabela36[[#This Row],[Data]]) -> 2025 | D15: =TEXT(E15,"mmmm") -> dezembro | E15: 46006 | F15: ="01 a 14"&"/"&B15&"/"&A15 -> 01 a 14/12/2025 | G15: =3000+2500 -> 5500 | H15: =-SUMIFS('Despesas Detalhe'!$F:$F,'Despesas Detalhe'!$D:$D,">"&$E14,'Despesas Detalhe'!$D:$D,"<"&$E15) -> -3010 | I15: =-SUMIFS('Despesas Detalhe'!$F:$F,'Despesas Detalhe'!$E:$E,">"&$E14,'Despesas Detalhe'!$E:$E,"<"&$E15) -> -3010 | J15: =G15+I15 -> 2490 | K15: =IF((ABS(H15)+I15)<=0,"",ABS(H15)+I15) | L15: =J15/G15 -> 0.45272727
A16: =YEAR(E16) -> 2025 | B16: =MONTH(E16) -> 12 | C16: =YEAR(Tabela36[[#This Row],[Data]]) -> 2025 | D16: =TEXT(E16,"mmmm") -> dezembro | E16: 46021 | F16: ="15 a 30"&"/"&B15&"/"&A15 -> 15 a 30/12/2025 | G16: =2200+2000 -> 4200 | H16: =-SUMIFS('Despesas Detalhe'!$F:$F,'Despesas Detalhe'!$D:$D,">="&$E15,'Despesas Detalhe'!$D:$D,"<="&$E16) -> -2551 | I16: =-SUMIFS('Despesas Detalhe'!$F:$F,'Despesas Detalhe'!$E:$E,">="&$E15,'Despesas Detalhe'!$E:$E,"<="&$E16) -> -2551 | J16: =G16+I16 -> 1649 | K16: =IF((ABS(H16)+I16)<=0,"",ABS(H16)+I16) | L16: =J16/G16 -> 0.39261905

Sheet Fatores (Contas)
B2: Data | C2: Tipo de Gasto | D2: Status | E2: Contas
B4: 44896 | C4: Fixo | D4: Pago | E4: Luz | G4: Alta | J4: SIM
B5: 44897 | C5: Variável | D5: Não Pago | E5: Internet | G5: Média | J5: NÃO
B6: 44898 | E6: Plano Cel. (Douglas) | G6: Baixa
B7: 44899 | E7: Plano Cel. (Joyce)
B8: 44900 | E8: Água
B9: 44901 | E9: IPVA | H9: mensalidade | I9: uniforme
B10: 44902 | E10: Financiamento | H10: 1070 | I10: 800
B11: 44903 | E11: TV Box
B12: 44904 | E12: Empréstimo - Vó
B13: 44905 | E13: Cartão Nubank
B14: 44906 | E14: Licenciamento
B15: 44907
B16: 44908
B17: 44909
B18: 44910
B19: 44911
B20: 44912
B21: 44913
B22: 44914
B23: 44915
B24: 44916
B25: 44917
B26: 44918
... B399: 45291
